<robot name ="mrdp">

 <link name="base_link">
  <visual>
   <geometry>
     <box size="2 2 0.1" />
   </geometry>
 </visual>
 </link>

 <link name="wheel_right">
  <visual>
   <geometry>
    <cylinder length="0.2" radius="0.4" />
   </geometry>
   <material name="blue">
    <color rgba="0 0 0.8 1" />
   </material>
   <origin rpy="1.57075 0 0" xyz="0 0 0" />
  </visual>
 </link>
 
 <joint name="base_to_right_wheel" type="continuous">
  <parent link="base_link" />
  <child link="wheel_right" />
  <origin xyz="0 -1.2 0" />
 </joint>

 <link name="wheel_left">
  <visual>
   <geometry>
    <cylinder length="0.2" radius="0.4" />
   </geometry>
   <material name="blue">
    <color rgba="0 0 0.8 1" />
   </material>
   <origin rpy="1.57075 0 0" xyz="0 0 0" />
  </visual>
 </link>
 
 <joint name="base_to_left_wheel" type="continuous">
  <parent link="base_link" />
  <child link="wheel_left" />
  <origin xyz="0 1.2 0" />
 </joint>

 <link name="support1">
  <visual>
   <geometry>
    <cylinder length="1" radius="0.01" />
   </geometry>
   <material name="white">
    <color rgba="1 1 1 1" />
   </material>
   <origin rpy="0 0 0" xyz="0 0 0.5" />
  </visual>
 </link>
 
 <joint name="support1_baselink" type="fixed">
  <parent link="base_link" />
  <child link="support1" />
  <origin xyz="1 1 0" />
 </joint>

<link name="support2">
  <visual>
   <geometry>
    <cylinder length="1" radius="0.01" />
   </geometry>
   <material name="white">
    <color rgba="1 1 1 1" />
   </material>
   <origin rpy="0 0 0" xyz="0 0 0.5" />
  </visual>
 </link>
 
 <joint name="support2_baselink" type="fixed">
  <parent link="base_link" />
  <child link="support2" />
  <origin xyz="1 -1 0" />
 </joint>

<link name="support3">
  <visual>
   <geometry>
    <cylinder length="1" radius="0.01" />
   </geometry>
   <material name="white">
    <color rgba="1 1 1 1" />
   </material>
   <origin rpy="0 0 0" xyz="0 0 0.5" />
  </visual>
 </link>
 
 <joint name="support3_baselink" type="fixed">
  <parent link="base_link" />
  <child link="support3" />
  <origin xyz="-1 1 0" />
 </joint>

<link name="support4">
  <visual>
   <geometry>
    <cylinder length="1" radius="0.01" />
   </geometry>
   <material name="white">
    <color rgba="1 1 1 1" />
   </material>
   <origin rpy="0 0 0" xyz="0 0 0.5" />
  </visual>
 </link>
 
 <joint name="support4_baselink" type="fixed">
  <parent link="base_link" />
  <child link="support4" />
  <origin xyz="-1 -1 0" />
 </joint>

 <link name="kinect_base">
  <visual>
   <geometry>
     <box size="2 2 0.1" />
   </geometry>
  <origin rpy="0 0 0" xyz="-1 -1 0" />
 </visual>
 </link>

 <joint name="kinectbase_support1" type="fixed">
  <parent link="support1" />
  <child link="kinect_base" />
  <origin xyz="0 0 1" />
 </joint>

 <link name="camera_link">
  <visual>
   <geometry>
     <box size="1.5 0.5 0.5" />
   </geometry>
  <material name="green">
    <color rgba="0 0 0 1" />
  </material>
  <origin rpy="0 0 1.5707" xyz="0 0 0" />
 </visual>
 </link>

 <joint name="kinect_kinectbase" type="fixed">
  <parent link="kinect_base" />
  <child link="camera_link" />
  <origin xyz="-0.25 -1 0.25" />
 </joint>

 
</robot>
